<sdf version="1.6">
  <model name="remaro">
    <link name="link_base">
      <pose frame="">0 0 0 0 -0 0</pose>
      <inertial>
        <pose frame="">0.238118 -0.019651 -0.125666 0 -0 0</pose>
        <mass>13.454</mass>
        <inertia>
          <ixx>0.476216</ixx>
          <ixy>-0.0831102</ixy>
          <ixz>0.0449136</ixz>
          <iyy>11.0437</iyy>
          <iyz>0.0286642</iyz>
          <izz>10.8654</izz>
        </inertia>
      </inertial>
      <collision name="link_base_fixed_joint_lump__base_collision">
        <pose frame="">-0.00055 1e-05 -5e-05 0 -0 0</pose>
        <geometry>
          <mesh>
            <scale>1 1 1</scale>
            <uri>model://remaro_package/meshes/dae/base.000.dae</uri>
          </mesh>
        </geometry>
      </collision>
      <collision name="link_base_fixed_joint_lump__cam_bottom_collision_1">
        <pose frame="">1.11613 0 -0.27587 0 -0 0</pose>
        <geometry>
          <mesh>
            <scale>1 1 1</scale>
            <uri>model://remaro_package/meshes/dae/cam_bottom.000.dae</uri>
          </mesh>
        </geometry>
      </collision>
      <collision name="link_base_fixed_joint_lump__cam_front_collision_2">
        <pose frame="">1.4231 -0.00323 -0.0191 0 -0 0</pose>
        <geometry>
          <mesh>
            <scale>1 1 1</scale>
            <uri>model://remaro_package/meshes/dae/cam_front.000.dae</uri>
          </mesh>
        </geometry>
      </collision>
      <collision name="link_base_fixed_joint_lump__dvl_collision_3">
        <pose frame="">-0.63433 0 -0.27529 0 -0 0</pose>
        <geometry>
          <mesh>
            <scale>1 1 1</scale>
            <uri>model://remaro_package/meshes/dae/dvl.000.dae</uri>
          </mesh>
        </geometry>
      </collision>
      <collision name="link_base_fixed_joint_lump__fls_collision_4">
        <pose frame="">1.39819 0 -0.2032 0 -0 0</pose>
        <geometry>
          <mesh>
            <scale>1 1 1</scale>
            <uri>model://remaro_package/meshes/dae/fls.000.dae</uri>
          </mesh>
        </geometry>
      </collision>
      <collision name="link_base_fixed_joint_lump__laser_collision_5">
        <pose frame="">-0.93634 0 -0.27155 0 -0 0</pose>
        <geometry>
          <mesh>
            <scale>1 1 1</scale>
            <uri>model://remaro_package/meshes/dae/laser.000.dae</uri>
          </mesh>
        </geometry>
      </collision>
      <collision name="link_base_fixed_joint_lump__light_pair_bottom_collision_6">
        <pose frame="">1.11609 0 -0.25373 0 -0 0</pose>
        <geometry>
          <mesh>
            <scale>1 1 1</scale>
            <uri>model://remaro_package/meshes/dae/light_pair_bottom.000.dae</uri>
          </mesh>
        </geometry>
      </collision>
      <collision name="link_base_fixed_joint_lump__light_pair_front_collision_7">
        <pose frame="">1.40625 0 -0.01758 0 -0 0</pose>
        <geometry>
          <mesh>
            <scale>1 1 1</scale>
            <uri>model://remaro_package/meshes/dae/light_pair_front.000.dae</uri>
          </mesh>
        </geometry>
      </collision>
      <collision name="link_base_fixed_joint_lump__mbes_collision_8">
        <pose frame="">-0.00074 0 -0.2658 0 -0 0</pose>
        <geometry>
          <mesh>
            <scale>1 1 1</scale>
            <uri>model://remaro_package/meshes/dae/mbes.000.dae</uri>
          </mesh>
        </geometry>
      </collision>
      <collision name="link_base_fixed_joint_lump__scanner_side_collision_9">
        <pose frame="">-0.08613 -0.27032 -0.01727 0 -0 0</pose>
        <geometry>
          <mesh>
            <scale>1 1 1</scale>
            <uri>model://remaro_package/meshes/dae/scanner_side.000.dae</uri>
          </mesh>
        </geometry>
      </collision>
      <collision name="link_base_fixed_joint_lump__scanner_top_collision_10">
        <pose frame="">-0.08613 0 0.25305 0 -0 0</pose>
        <geometry>
          <mesh>
            <scale>1 1 1</scale>
            <uri>model://remaro_package/meshes/dae/scanner_top.000.dae</uri>
          </mesh>
        </geometry>
      </collision>
      <collision name="link_base_fixed_joint_lump__sss_left_collision_11">
        <pose frame="">-0.07144 0.1711 -0.1976 0 -0 0</pose>
        <geometry>
          <mesh>
            <scale>1 1 1</scale>
            <uri>model://remaro_package/meshes/dae/sss_left.000.dae</uri>
          </mesh>
        </geometry>
      </collision>
      <collision name="link_base_fixed_joint_lump__sss_right_collision_12">
        <pose frame="">-0.07144 -0.17086 -0.19741 0 -0 0</pose>
        <geometry>
          <mesh>
            <scale>1 1 1</scale>
            <uri>model://remaro_package/meshes/dae/sss_right.000.dae</uri>
          </mesh>
        </geometry>
      </collision>
      <visual name="link_base_fixed_joint_lump__base_visual">
        <pose frame="">0 0 0 0 -0 0</pose>
        <geometry>
          <mesh>
            <scale>1 1 1</scale>
            <uri>model://remaro_package/meshes/dae/base.dae</uri>
          </mesh>
        </geometry>
      </visual>
      <visual name="link_base_fixed_joint_lump__cam_bottom_visual_1">
        <pose frame="">1.11613 0 -0.27517 0 -0 0</pose>
        <geometry>
          <mesh>
            <scale>1 1 1</scale>
            <uri>model://remaro_package/meshes/dae/cam_bottom.dae</uri>
          </mesh>
        </geometry>
      </visual>
      <visual name="link_base_fixed_joint_lump__cam_front_visual_2">
        <pose frame="">1.42246 -0.00323 -0.0191 0 -0 0</pose>
        <geometry>
          <mesh>
            <scale>1 1 1</scale>
            <uri>model://remaro_package/meshes/dae/cam_front.dae</uri>
          </mesh>
        </geometry>
      </visual>
      <visual name="link_base_fixed_joint_lump__dvl_visual_3">
        <pose frame="">-0.63435 0 -0.27426 0 -0 0</pose>
        <geometry>
          <mesh>
            <scale>1 1 1</scale>
            <uri>model://remaro_package/meshes/dae/dvl.dae</uri>
          </mesh>
        </geometry>
      </visual>
      <visual name="link_base_fixed_joint_lump__fin_bar_visual_4">
        <pose frame="">-1.23781 -0.00191 -0.01932 0 -0 0</pose>
        <geometry>
          <mesh>
            <scale>1 1 1</scale>
            <uri>model://remaro_package/meshes/dae/fin_bar.dae</uri>
          </mesh>
        </geometry>
      </visual>
      <visual name="link_base_fixed_joint_lump__fls_visual_5">
        <pose frame="">1.39813 0 -0.20309 0 -0 0</pose>
        <geometry>
          <mesh>
            <scale>1 1 1</scale>
            <uri>model://remaro_package/meshes/dae/fls.dae</uri>
          </mesh>
        </geometry>
      </visual>
      <visual name="link_base_fixed_joint_lump__laser_visual_6">
        <pose frame="">-0.9365 6e-05 -0.27134 0 -0 0</pose>
        <geometry>
          <mesh>
            <scale>1 1 1</scale>
            <uri>model://remaro_package/meshes/dae/laser.dae</uri>
          </mesh>
        </geometry>
      </visual>
      <visual name="link_base_fixed_joint_lump__light_pair_bottom_visual_7">
        <pose frame="">1.11609 0 -0.25359 0 -0 0</pose>
        <geometry>
          <mesh>
            <scale>1 1 1</scale>
            <uri>model://remaro_package/meshes/dae/light_pair_bottom.dae</uri>
          </mesh>
        </geometry>
      </visual>
      <visual name="link_base_fixed_joint_lump__light_pair_front_visual_8">
        <pose frame="">1.40611 0 -0.01758 0 -0 0</pose>
        <geometry>
          <mesh>
            <scale>1 1 1</scale>
            <uri>model://remaro_package/meshes/dae/light_pair_front.dae</uri>
          </mesh>
        </geometry>
      </visual>
      <visual name="link_base_fixed_joint_lump__mbes_visual_9">
        <pose frame="">-0.00147 0 -0.26642 0 -0 0</pose>
        <geometry>
          <mesh>
            <scale>1 1 1</scale>
            <uri>model://remaro_package/meshes/dae/mbes.dae</uri>
          </mesh>
        </geometry>
      </visual>
      <visual name="link_base_fixed_joint_lump__scanner_side_visual_10">
        <pose frame="">-0.08613 -0.27004 -0.01727 0 -0 0</pose>
        <geometry>
          <mesh>
            <scale>1 1 1</scale>
            <uri>model://remaro_package/meshes/dae/scanner_side.dae</uri>
          </mesh>
        </geometry>
      </visual>
      <visual name="link_base_fixed_joint_lump__scanner_top_visual_11">
        <pose frame="">-0.08613 0 0.25277 0 -0 0</pose>
        <geometry>
          <mesh>
            <scale>1 1 1</scale>
            <uri>model://remaro_package/meshes/dae/scanner_top.dae</uri>
          </mesh>
        </geometry>
      </visual>
      <visual name="link_base_fixed_joint_lump__sss_left_visual_12">
        <pose frame="">-0.07144 0.17093 -0.19748 0 -0 0</pose>
        <geometry>
          <mesh>
            <scale>1 1 1</scale>
            <uri>model://remaro_package/meshes/dae/sss_left.dae</uri>
          </mesh>
        </geometry>
      </visual>
      <visual name="link_base_fixed_joint_lump__sss_right_visual_13">
        <pose frame="">-0.07144 -0.17093 -0.19748 0 -0 0</pose>
        <geometry>
          <mesh>
            <scale>1 1 1</scale>
            <uri>model://remaro_package/meshes/dae/sss_right.dae</uri>
          </mesh>
        </geometry>
      </visual>
    </link>
    <link name="link_fin_pair_h">
      <pose frame="">-1.23634 -0.00191 -0.01932 0 -0 0</pose>
      <inertial>
        <pose frame="">0 0 0 0 -0 0</pose>
        <mass>0.961</mass>
        <inertia>
          <ixx>0.69678</ixx>
          <ixy>0</ixy>
          <ixz>0</ixz>
          <iyy>0.02607</iyy>
          <iyz>0</iyz>
          <izz>0.72155</izz>
        </inertia>
      </inertial>
      <collision name="link_fin_pair_h_fixed_joint_lump__fin_pair_h_collision">
        <pose frame="">-0.00073 0 0 0 -0 0</pose>
        <geometry>
          <mesh>
            <scale>1 1 1</scale>
            <uri>model://remaro_package/meshes/dae/fin_pair_h.000.dae</uri>
          </mesh>
        </geometry>
      </collision>
      <visual name="link_fin_pair_h_fixed_joint_lump__fin_pair_h_visual">
        <pose frame="">0 0 0 0 -0 0</pose>
        <geometry>
          <mesh>
            <scale>1 1 1</scale>
            <uri>model://remaro_package/meshes/dae/fin_pair_h.dae</uri>
          </mesh>
        </geometry>
      </visual>
    </link>
    <joint name="joint_fin_pair_h" type="revolute">
      <child>link_fin_pair_h</child>
      <parent>link_base</parent>
      <axis>
        <xyz>0 1 0</xyz>
        <limit>
          <lower>-1.08</lower>
          <upper>1.08</upper>
          <effort>0</effort>
          <velocity>0</velocity>
        </limit>
        <dynamics>
          <spring_reference>0</spring_reference>
          <spring_stiffness>0</spring_stiffness>
        </dynamics>
        <use_parent_model_frame>1</use_parent_model_frame>
      </axis>
    </joint>
    <link name="link_fin_pair_v">
      <pose frame="">-1.23631 0 -0.01932 1.5708 -0 0</pose>
      <inertial>
        <pose frame="">0 0 0 0 -0 0</pose>
        <mass>0.961</mass>
        <inertia>
          <ixx>0.86184</ixx>
          <ixy>0</ixy>
          <ixz>0</ixz>
          <iyy>0.89248</iyy>
          <iyz>0</iyz>
          <izz>0.03224</izz>
        </inertia>
      </inertial>
      <collision name="link_fin_pair_v_fixed_joint_lump__fin_pair_v_collision">
        <pose frame="">-0.00077 0 0 -1.5708 0 0</pose>
        <geometry>
          <mesh>
            <scale>1 1 1</scale>
            <uri>model://remaro_package/meshes/dae/fin_pair_v.000.dae</uri>
          </mesh>
        </geometry>
      </collision>
      <visual name="link_fin_pair_v_fixed_joint_lump__fin_pair_v_visual">
        <pose frame="">0 0 0 -1.5708 0 0</pose>
        <geometry>
          <mesh>
            <scale>1 1 1</scale>
            <uri>model://remaro_package/meshes/dae/fin_pair_v.dae</uri>
          </mesh>
        </geometry>
      </visual>
    </link>
    <joint name="joint_fin_pair_v" type="revolute">
      <child>link_fin_pair_v</child>
      <parent>link_base</parent>
      <axis>
        <xyz>0 -4e-06 1</xyz>
        <limit>
          <lower>-1.08</lower>
          <upper>1.08</upper>
          <effort>0</effort>
          <velocity>0</velocity>
        </limit>
        <dynamics>
          <spring_reference>0</spring_reference>
          <spring_stiffness>0</spring_stiffness>
        </dynamics>
        <use_parent_model_frame>1</use_parent_model_frame>
      </axis>
    </joint>
    <link name="link_prop">
      <pose frame="">-1.48074 0 -0.01932 0 -0 1.5708</pose>
      <inertial>
        <pose frame="">0 0 0 0 -0 0</pose>
        <mass>0.961</mass>
        <inertia>
          <ixx>0.0036</ixx>
          <ixy>0</ixy>
          <ixz>0</ixz>
          <iyy>0.0021</iyy>
          <iyz>0</iyz>
          <izz>0.0021</izz>
        </inertia>
      </inertial>
      <collision name="link_prop_fixed_joint_lump__prop_collision">
        <pose frame="">0 -0.00054 0 0 0 -1.5708</pose>
        <geometry>
          <mesh>
            <scale>1 1 1</scale>
            <uri>model://remaro_package/meshes/dae/prop.000.dae</uri>
          </mesh>
        </geometry>
      </collision>
      <visual name="link_prop_fixed_joint_lump__prop_visual">
        <pose frame="">0 0 0 0 0 -1.5708</pose>
        <geometry>
          <mesh>
            <scale>1 1 1</scale>
            <uri>model://remaro_package/meshes/dae/prop.dae</uri>
          </mesh>
        </geometry>
      </visual>
    </link>
    <joint name="joint_prop" type="revolute">
      <child>link_prop</child>
      <parent>link_base</parent>
      <axis>
        <xyz>-1 -4e-06 0</xyz>
        <limit>
          <lower>-1e+16</lower>
          <upper>1e+16</upper>
        </limit>
        <dynamics>
          <spring_reference>0</spring_reference>
          <spring_stiffness>0</spring_stiffness>
        </dynamics>
        <use_parent_model_frame>1</use_parent_model_frame>
      </axis>
    </joint>
  </model>
</sdf>
